<?xml version="1.0" encoding="utf-8"?>
<!-- This URDF was automatically created by SolidWorks to URDF Exporter! Originally created by Stephen Brawner (brawner@gmail.com) 
     Commit Version: 1.5.1-0-g916b5db  Build Version: 1.5.7152.31018
     For more information, please see http://wiki.ros.org/sw_urdf_exporter -->
<robot
  name="rom1_description">
  <link
    name="base_link">
    <inertial>
      <origin
        xyz="0.024878 0.0018662 0.064393"
        rpy="0 0 0" />
      <mass
        value="14.934" />
      <inertia
        ixx="0.50162"
        ixy="-0.00097962"
        ixz="0.018772"
        iyy="0.46255"
        iyz="-0.00017887"
        izz="0.90672" />
    </inertial>
    <visual>
      <origin
        xyz="0 0 0"
        rpy="0 0 0" />
      <geometry>
        <mesh
          filename="package://rom1_description/meshes/base_link.STL" />
      </geometry>
      <material
        name="">
        <!--color rgba="0.89804 0.91765 0.92941 1" /-->
        <color rgba="1.0 0.4235294118 0.0392156863 1.0" />
      </material>
    </visual>
    <collision>
      <origin
        xyz="0 0 0"
        rpy="0 0 0" />
      <geometry>
        <mesh
          filename="package://rom1_description/meshes/base_link.STL" />
      </geometry>
    </collision>
  </link>
  <link
    name="front_right_wheel">
    <inertial>
      <origin
        xyz="-2.7062E-16 -0.0009488 -6.9389E-17"
        rpy="0 0 0" />
      <mass
        value="2.8826" />
      <inertia
        ixx="0.0029015"
        ixy="-1.6738E-17"
        ixz="2.432E-19"
        iyy="0.00525"
        iyz="9.3041E-19"
        izz="0.0029015" />
    </inertial>
    <visual>
      <origin
        xyz="0 0 0"
        rpy="0 0 0" />
      <geometry>
        <mesh
          filename="package://rom1_description/meshes/front_right_wheel.STL" />
      </geometry>
      <material
        name="">
        <!-- <color rgba="0.29804 0.29804 0.29804 1" /> -->
        <color rgba="1.0 1.0 1.0 1" />
      </material>
    </visual>
    <collision>
      <origin
        xyz="0 0 0"
        rpy="0 0 0" />
      <geometry>
        <mesh
          filename="package://rom1_description/meshes/front_right_wheel.STL" />
      </geometry>
    </collision>
  </link>
  <joint
    name="front_right_wheel_joint"
    type="continuous">
    <origin
      xyz="0.05425 -0.22 -0.028997"
      rpy="0 0 0" />
    <parent
      link="base_link" />
    <child
      link="front_right_wheel" />
    <axis
      xyz="0 1 0" />
  </joint>
  <link
    name="back_right_wheel">
    <inertial>
      <origin
        xyz="6.9389E-17 -0.0009488 2.7756E-17"
        rpy="0 0 0" />
      <mass
        value="2.8826" />
      <inertia
        ixx="0.0029015"
        ixy="-1.5199E-17"
        ixz="-1.4949E-19"
        iyy="0.00525"
        iyz="2.7321E-19"
        izz="0.0029015" />
    </inertial>
    <visual>
      <origin
        xyz="0 0 0"
        rpy="0 0 0" />
      <geometry>
        <mesh
          filename="package://rom1_description/meshes/back_right_wheel.STL" />
      </geometry>
      <material
        name="">
        <!-- <color rgba="0.29804 0.29804 0.29804 1" /> -->
           <color rgba="1.0 1.0 1.0 1" />
      </material>
    </visual>
    <collision>
      <origin
        xyz="0 0 0"
        rpy="0 0 0" />
      <geometry>
        <mesh
          filename="package://rom1_description/meshes/back_right_wheel.STL" />
      </geometry>
    </collision>
  </link>
  <joint
    name="back_right_wheel_joint"
    type="continuous">
    <origin
      xyz="-0.05425 -0.22 -0.028997"
      rpy="0 0 0" />
    <parent
      link="base_link" />
    <child
      link="back_right_wheel" />
    <axis
      xyz="0 1 0" />
  </joint>
  <link
    name="front_left_wheel">
    <inertial>
      <origin
        xyz="-6.8834E-15 0.0009488 -1.5682E-15"
        rpy="0 0 0" />
      <mass
        value="2.8826" />
      <inertia
        ixx="0.0029015"
        ixy="-1.5963E-17"
        ixz="-2.3471E-19"
        iyy="0.00525"
        iyz="3.099E-18"
        izz="0.0029015" />
    </inertial>
    <visual>
      <origin
        xyz="0 0 0"
        rpy="0 0 0" />
      <geometry>
        <mesh
          filename="package://rom1_description/meshes/front_left_wheel.STL" />
      </geometry>
      <material
        name="">
        <!-- <color rgba="0.29804 0.29804 0.29804 1" /> -->
           <color rgba="1.0 1.0 1.0 1" />
      </material>
    </visual>
    <collision>
      <origin
        xyz="0 0 0"
        rpy="0 0 0" />
      <geometry>
        <mesh
          filename="package://rom1_description/meshes/front_left_wheel.STL" />
      </geometry>
    </collision>
  </link>
  <joint
    name="front_left_wheel_joint"
    type="continuous">
    <origin
      xyz="0.05425 0.22 -0.029"
      rpy="0 0 0" />
    <parent
      link="base_link" />
    <child
      link="front_left_wheel" />
    <axis
      xyz="0 1 0" />
  </joint>
  <link
    name="back_left_wheel">
    <inertial>
      <origin
        xyz="-6.7099E-15 0.0009488 -1.8041E-15"
        rpy="0 0 0" />
      <mass
        value="2.8826" />
      <inertia
        ixx="0.0029015"
        ixy="-1.6306E-17"
        ixz="2.1705E-19"
        iyy="0.00525"
        iyz="3.4145E-18"
        izz="0.0029015" />
    </inertial>
    <visual>
      <origin
        xyz="0 0 0"
        rpy="0 0 0" />
      <geometry>
        <mesh
          filename="package://rom1_description/meshes/back_left_wheel.STL" />
      </geometry>
      <material
        name="">
        <!-- <color rgba="0.29804 0.29804 0.29804 1" /> -->
         <color rgba="1.0 1.0 1.0 1" />
      </material>
    </visual>
    <collision>
      <origin
        xyz="0 0 0"
        rpy="0 0 0" />
      <geometry>
        <mesh
          filename="package://rom1_description/meshes/back_left_wheel.STL" />
      </geometry>
    </collision>
  </link>
  <joint
    name="back_left_wheel_joint"
    type="continuous">
    <origin
      xyz="-0.05425 0.22 -0.029"
      rpy="0 0 0" />
    <parent
      link="base_link" />
    <child
      link="back_left_wheel" />
    <axis
      xyz="0 1 0" />
  </joint>

      <transmission name="motor1">
    <type>transmission_interface/SimpleTransmission</type>
    <joint name="front_right_wheel_joint">
        <hardwareInterface>hardware_interface/VelocityJointInterface</hardwareInterface>
    </joint>
    <actuator name="actuator1">
        <hardwareInterface>hardware_interface/VelocityJointInterface</hardwareInterface>
        <mechanicalReduction>1</mechanicalReduction>
    </actuator>
  </transmission>
  
  <transmission name="motor2">
    <type>transmission_interface/SimpleTransmission</type>
    <joint name="front_left_wheel_joint">
        <hardwareInterface>hardware_interface/VelocityJointInterface</hardwareInterface>
    </joint>
    <actuator name="actuator2">
        <hardwareInterface>hardware_interface/VelocityJointInterface</hardwareInterface>
        <mechanicalReduction>1</mechanicalReduction>
    </actuator>
  </transmission>

  <transmission name="motor3">
    <type>transmission_interface/SimpleTransmission</type>
    <joint name="back_right_wheel_joint">
        <hardwareInterface>hardware_interface/VelocityJointInterface</hardwareInterface>
    </joint>
    <actuator name="actuator3">
        <hardwareInterface>hardware_interface/VelocityJointInterface</hardwareInterface>
        <mechanicalReduction>1</mechanicalReduction>
    </actuator>
  </transmission>

  <transmission name="motor4">
    <type>transmission_interface/SimpleTransmission</type>
    <joint name="back_left_wheel_joint">
        <hardwareInterface>hardware_interface/VelocityJointInterface</hardwareInterface>
    </joint>
    <actuator name="actuator4">
        <hardwareInterface>hardware_interface/VelocityJointInterface</hardwareInterface>
        <mechanicalReduction>1</mechanicalReduction>
    </actuator>
  </transmission>

<gazebo>
    <plugin name="gazebo_ros_control" filename="libgazebo_ros_control.so"> 
      <robotNamespace>rom1</robotNamespace>
    </plugin>
</gazebo>


</robot>