<?xml version="1.0" encoding="utf-8"?>
<!-- This URDF was automatically created by SolidWorks to URDF Exporter! Originally created by Stephen Brawner (brawner@gmail.com) 
     Commit Version: 1.5.1-0-g916b5db  Build Version: 1.5.7152.31018
     For more information, please see http://wiki.ros.org/sw_urdf_exporter -->
<robot
  name="rom1">
  <link
    name="base_link">
    <inertial>
      <origin
        xyz="0.0017571 0.0013787 -0.019582"
        rpy="0 0 0" />
      <mass
        value="1.4621" />
      <inertia
        ixx="0.0046154"
        ixy="3.5862E-06"
        ixz="-3.9803E-06"
        iyy="0.0095142"
        iyz="9.1626E-07"
        izz="0.013244" />
    </inertial>
    <visual>
      <origin
        xyz="0 0 0"
        rpy="0 0 0" />
      <geometry>
        <mesh
          filename="package://rom1_description/meshes/base_link.STL" />
      </geometry>
      <material
        name="">
        <color
          rgba="0.89804 0.91765 0.92941 1" />
      </material>
    </visual>
    <collision>
      <origin
        xyz="0 0 0"
        rpy="0 0 0" />
      <geometry>
        <mesh
          filename="package://rom1_description/meshes/base_link.STL" />
      </geometry>
    </collision>
  </link>
  <link
    name="front_right_wheel">
    <inertial>
      <origin
        xyz="-5.5511E-17 -0.0009488 3.1225E-17"
        rpy="0 0 0" />
      <mass
        value="2.8826" />
      <inertia
        ixx="0.0029015"
        ixy="6.7227E-19"
        ixz="-4.7058E-19"
        iyy="0.00525"
        iyz="5.8226E-19"
        izz="0.0029015" />
    </inertial>
    <visual>
      <origin
        xyz="0 0 0"
        rpy="0 0 0" />
      <geometry>
        <mesh
          filename="package://rom1_description/meshes/front_right_wheel.STL" />
      </geometry>
      <material
        name="">
        <color
          rgba="0.01 0.01 0.43725 1" />
      </material>
    </visual>
    <collision>
      <origin
        xyz="0 0 0"
        rpy="0 0 0" />
      <geometry>
        <mesh
          filename="package://rom1_description/meshes/front_right_wheel.STL" />
      </geometry>
    </collision>
  </link>
  <joint
    name="front_right_wheel_joint"
    type="continuous">
    <origin
      xyz="0.062204 -0.22142 -0.027014"
      rpy="0 0 0" />
    <parent
      link="base_link" />
    <child
      link="front_right_wheel" />
    <axis
      xyz="0 1 0" />
  </joint>
  <link
    name="front_left_wheel">
    <inertial>
      <origin
        xyz="-7.3219E-14 0.0009488 1.6442E-13"
        rpy="0 0 0" />
      <mass
        value="2.8826" />
      <inertia
        ixx="0.0029015"
        ixy="3.5176E-15"
        ixz="-7.253E-15"
        iyy="0.00525"
        iyz="-8.8944E-15"
        izz="0.0029015" />
    </inertial>
    <visual>
      <origin
        xyz="0 0 0"
        rpy="0 0 0" />
      <geometry>
        <mesh
          filename="package://rom1_description/meshes/front_left_wheel.STL" />
      </geometry>
      <material
        name="">
        <color
          rgba="0.01 0.01 0.43725 1" />
      </material>
    </visual>
    <collision>
      <origin
        xyz="0 0 0"
        rpy="0 0 0" />
      <geometry>
        <mesh
          filename="package://rom1_description/meshes/front_left_wheel.STL" />
      </geometry>
    </collision>
  </link>
  <joint
    name="front_left_wheel_joint"
    type="continuous">
    <origin
      xyz="0.060348 0.22358 -0.027014"
      rpy="0 0 0" />
    <parent
      link="base_link" />
    <child
      link="front_left_wheel" />
    <axis
      xyz="0 1 0" />
  </joint>
  <link
    name="back_left_wheel">
    <inertial>
      <origin
        xyz="-1.1102E-16 0.0009488 1.7347E-17"
        rpy="0 0 0" />
      <mass
        value="2.8826" />
      <inertia
        ixx="0.0029015"
        ixy="-2.0383E-17"
        ixz="-8.4465E-19"
        iyy="0.00525"
        iyz="1.0126E-18"
        izz="0.0029015" />
    </inertial>
    <visual>
      <origin
        xyz="0 0 0"
        rpy="0 0 0" />
      <geometry>
        <mesh
          filename="package://rom1_description/meshes/back_left_wheel.STL" />
      </geometry>
      <material
        name="">
        <color
          rgba="0.01 0.01 0.43725 1" />
      </material>
    </visual>
    <collision>
      <origin
        xyz="0 0 0"
        rpy="0 0 0" />
      <geometry>
        <mesh
          filename="package://rom1_description/meshes/back_left_wheel.STL" />
      </geometry>
    </collision>
  </link>
  <joint
    name="back_left_wheel_joint"
    type="continuous">
    <origin
      xyz="-0.063652 0.22358 -0.027014"
      rpy="0 0 0" />
    <parent
      link="base_link" />
    <child
      link="back_left_wheel" />
    <axis
      xyz="0 1 0" />
  </joint>
  <link
    name="back_right_wheel">
    <inertial>
      <origin
        xyz="-2.2204E-16 -0.0009488 -1.0408E-17"
        rpy="0 0 0" />
      <mass
        value="2.8826" />
      <inertia
        ixx="0.0029015"
        ixy="4.3227E-19"
        ixz="6.4507E-20"
        iyy="0.00525"
        iyz="4.6936E-19"
        izz="0.0029015" />
    </inertial>
    <visual>
      <origin
        xyz="0 0 0"
        rpy="0 0 0" />
      <geometry>
        <mesh
          filename="package://rom1_description/meshes/back_right_wheel.STL" />
      </geometry>
      <material
        name="">
        <color
          rgba="0.01 0.01 0.43725 1" />
      </material>
    </visual>
    <collision>
      <origin
        xyz="0 0 0"
        rpy="0 0 0" />
      <geometry>
        <mesh
          filename="package://rom1_description/meshes/back_right_wheel.STL" />
      </geometry>
    </collision>
  </link>
  <joint
    name="back_right_wheel_joint"
    type="continuous">
    <origin
      xyz="-0.061796 -0.22142 -0.027014"
      rpy="0 0 0" />
    <parent
      link="base_link" />
    <child
      link="back_right_wheel" />
    <axis
      xyz="0 1 0" />
  </joint>

  <transmission name="motor1">
    <type>transmission_interface/SimpleTransmission</type>
    <joint name="front_right_wheel_joint">
        <hardwareInterface>hardware_interface/VelocityJointInterface</hardwareInterface>
    </joint>
    <actuator name="actuator1">
        <hardwareInterface>hardware_interface/VelocityJointInterface</hardwareInterface>
        <mechanicalReduction>1</mechanicalReduction>
    </actuator>
  </transmission>
  
  <transmission name="motor2">
    <type>transmission_interface/SimpleTransmission</type>
    <joint name="front_left_wheel_joint">
        <hardwareInterface>hardware_interface/VelocityJointInterface</hardwareInterface>
    </joint>
    <actuator name="actuator2">
        <hardwareInterface>hardware_interface/VelocityJointInterface</hardwareInterface>
        <mechanicalReduction>1</mechanicalReduction>
    </actuator>
  </transmission>

  <transmission name="motor3">
    <type>transmission_interface/SimpleTransmission</type>
    <joint name="back_right_wheel_joint">
        <hardwareInterface>hardware_interface/VelocityJointInterface</hardwareInterface>
    </joint>
    <actuator name="actuator3">
        <hardwareInterface>hardware_interface/VelocityJointInterface</hardwareInterface>
        <mechanicalReduction>1</mechanicalReduction>
    </actuator>
  </transmission>

  <transmission name="motor4">
    <type>transmission_interface/SimpleTransmission</type>
    <joint name="back_left_wheel_joint">
        <hardwareInterface>hardware_interface/VelocityJointInterface</hardwareInterface>
    </joint>
    <actuator name="actuator4">
        <hardwareInterface>hardware_interface/VelocityJointInterface</hardwareInterface>
        <mechanicalReduction>1</mechanicalReduction>
    </actuator>
  </transmission>

<gazebo>
    <plugin name="gazebo_ros_control" filename="libgazebo_ros_control.so"> 
      <robotNamespace>rom1</robotNamespace>
    </plugin>
</gazebo>
 
</robot>
